[2025-02-10T08:15:03.378+0000] {taskinstance.py:1171} INFO - Dependencies all met for <TaskInstance: pipeline_milestone_3.extract_data manual__2025-02-10T08:15:02.467570+00:00 [queued]>
[2025-02-10T08:15:03.383+0000] {taskinstance.py:1171} INFO - Dependencies all met for <TaskInstance: pipeline_milestone_3.extract_data manual__2025-02-10T08:15:02.467570+00:00 [queued]>
[2025-02-10T08:15:03.383+0000] {taskinstance.py:1368} INFO - 
--------------------------------------------------------------------------------
[2025-02-10T08:15:03.383+0000] {taskinstance.py:1369} INFO - Starting attempt 1 of 1
[2025-02-10T08:15:03.383+0000] {taskinstance.py:1370} INFO - 
--------------------------------------------------------------------------------
[2025-02-10T08:15:03.389+0000] {taskinstance.py:1389} INFO - Executing <Task(PythonOperator): extract_data> on 2025-02-10 08:15:02.467570+00:00
[2025-02-10T08:15:03.392+0000] {standard_task_runner.py:52} INFO - Started process 296 to run task
[2025-02-10T08:15:03.394+0000] {standard_task_runner.py:79} INFO - Running: ['***', 'tasks', 'run', 'pipeline_milestone_3', 'extract_data', 'manual__2025-02-10T08:15:02.467570+00:00', '--job-id', '11', '--raw', '--subdir', 'DAGS_FOLDER/P2M3_azka_irsyad_DAG.py', '--cfg-path', '/tmp/tmpj349yhfw', '--error-file', '/tmp/tmp5fmga50t']
[2025-02-10T08:15:03.395+0000] {standard_task_runner.py:80} INFO - Job 11: Subtask extract_data
[2025-02-10T08:15:03.423+0000] {task_command.py:371} INFO - Running <TaskInstance: pipeline_milestone_3.extract_data manual__2025-02-10T08:15:02.467570+00:00 [running]> on host c7bd35cc3dd3
[2025-02-10T08:15:03.456+0000] {taskinstance.py:1583} INFO - Exporting the following env vars:
AIRFLOW_CTX_DAG_OWNER=Azka
AIRFLOW_CTX_DAG_ID=pipeline_milestone_3
AIRFLOW_CTX_TASK_ID=extract_data
AIRFLOW_CTX_EXECUTION_DATE=2025-02-10T08:15:02.467570+00:00
AIRFLOW_CTX_TRY_NUMBER=1
AIRFLOW_CTX_DAG_RUN_ID=manual__2025-02-10T08:15:02.467570+00:00
[2025-02-10T08:15:03.461+0000] {base.py:68} INFO - Using connection ID '172.18.0.2' for task execution.
[2025-02-10T08:15:03.463+0000] {taskinstance.py:1902} ERROR - Task failed with exception
Traceback (most recent call last):
  File "/home/airflow/.local/lib/python3.7/site-packages/pandas/io/sql.py", line 2056, in execute
    cur.execute(*args, **kwargs)
psycopg2.errors.UndefinedTable: relation "table_m3" does not exist
LINE 1: SELECT * FROM table_m3
                      ^


The above exception was the direct cause of the following exception:

Traceback (most recent call last):
  File "/home/airflow/.local/lib/python3.7/site-packages/airflow/operators/python.py", line 171, in execute
    return_value = self.execute_callable()
  File "/home/airflow/.local/lib/python3.7/site-packages/airflow/operators/python.py", line 189, in execute_callable
    return self.python_callable(*self.op_args, **self.op_kwargs)
  File "/opt/airflow/dags/P2M3_azka_irsyad_DAG.py", line 21, in extract
    data_raw = pd.read_sql('SELECT * FROM table_m3', source_conn)
  File "/home/airflow/.local/lib/python3.7/site-packages/pandas/io/sql.py", line 608, in read_sql
    chunksize=chunksize,
  File "/home/airflow/.local/lib/python3.7/site-packages/pandas/io/sql.py", line 2116, in read_query
    cursor = self.execute(*args)
  File "/home/airflow/.local/lib/python3.7/site-packages/pandas/io/sql.py", line 2068, in execute
    raise ex from exc
pandas.io.sql.DatabaseError: Execution failed on sql 'SELECT * FROM table_m3': relation "table_m3" does not exist
LINE 1: SELECT * FROM table_m3
                      ^

[2025-02-10T08:15:03.467+0000] {taskinstance.py:1412} INFO - Marking task as FAILED. dag_id=pipeline_milestone_3, task_id=extract_data, execution_date=20250210T081502, start_date=20250210T081503, end_date=20250210T081503
[2025-02-10T08:15:03.471+0000] {standard_task_runner.py:97} ERROR - Failed to execute job 11 for task extract_data (Execution failed on sql 'SELECT * FROM table_m3': relation "table_m3" does not exist
LINE 1: SELECT * FROM table_m3
                      ^
; 296)
[2025-02-10T08:15:03.492+0000] {local_task_job.py:156} INFO - Task exited with return code 1
[2025-02-10T08:15:03.510+0000] {local_task_job.py:279} INFO - 0 downstream tasks scheduled from follow-on schedule check
