[2025-02-08T14:31:26.324+0000] {taskinstance.py:1171} INFO - Dependencies all met for <TaskInstance: pipeline_milestone_3.upload_to_elasticsearch manual__2025-02-08T14:31:23.017887+00:00 [queued]>
[2025-02-08T14:31:26.328+0000] {taskinstance.py:1171} INFO - Dependencies all met for <TaskInstance: pipeline_milestone_3.upload_to_elasticsearch manual__2025-02-08T14:31:23.017887+00:00 [queued]>
[2025-02-08T14:31:26.328+0000] {taskinstance.py:1368} INFO - 
--------------------------------------------------------------------------------
[2025-02-08T14:31:26.328+0000] {taskinstance.py:1369} INFO - Starting attempt 1 of 1
[2025-02-08T14:31:26.328+0000] {taskinstance.py:1370} INFO - 
--------------------------------------------------------------------------------
[2025-02-08T14:31:26.336+0000] {taskinstance.py:1389} INFO - Executing <Task(PythonOperator): upload_to_elasticsearch> on 2025-02-08 14:31:23.017887+00:00
[2025-02-08T14:31:26.338+0000] {standard_task_runner.py:52} INFO - Started process 215 to run task
[2025-02-08T14:31:26.340+0000] {standard_task_runner.py:79} INFO - Running: ['***', 'tasks', 'run', 'pipeline_milestone_3', 'upload_to_elasticsearch', 'manual__2025-02-08T14:31:23.017887+00:00', '--job-id', '81', '--raw', '--subdir', 'DAGS_FOLDER/ml_pipeline.py', '--cfg-path', '/tmp/tmpdp6vf1xf', '--error-file', '/tmp/tmp2jui7ot3']
[2025-02-08T14:31:26.341+0000] {standard_task_runner.py:80} INFO - Job 81: Subtask upload_to_elasticsearch
[2025-02-08T14:31:26.368+0000] {task_command.py:371} INFO - Running <TaskInstance: pipeline_milestone_3.upload_to_elasticsearch manual__2025-02-08T14:31:23.017887+00:00 [running]> on host fac8a5123a60
[2025-02-08T14:31:26.396+0000] {taskinstance.py:1583} INFO - Exporting the following env vars:
AIRFLOW_CTX_DAG_OWNER=Azka
AIRFLOW_CTX_DAG_ID=pipeline_milestone_3
AIRFLOW_CTX_TASK_ID=upload_to_elasticsearch
AIRFLOW_CTX_EXECUTION_DATE=2025-02-08T14:31:23.017887+00:00
AIRFLOW_CTX_TRY_NUMBER=1
AIRFLOW_CTX_DAG_RUN_ID=manual__2025-02-08T14:31:23.017887+00:00
[2025-02-08T14:31:26.399+0000] {base.py:299} WARNING - HEAD http://localhost:9200/ [status:N/A request:0.001s]
Traceback (most recent call last):
  File "/home/airflow/.local/lib/python3.7/site-packages/urllib3/connection.py", line 175, in _new_conn
    (self._dns_host, self.port), self.timeout, **extra_kw
  File "/home/airflow/.local/lib/python3.7/site-packages/urllib3/util/connection.py", line 95, in create_connection
    raise err
  File "/home/airflow/.local/lib/python3.7/site-packages/urllib3/util/connection.py", line 85, in create_connection
    sock.connect(sa)
ConnectionRefusedError: [Errno 111] Connection refused

During handling of the above exception, another exception occurred:

Traceback (most recent call last):
  File "/home/airflow/.local/lib/python3.7/site-packages/elasticsearch/connection/http_urllib3.py", line 252, in perform_request
    method, url, body, retries=Retry(False), headers=request_headers, **kw
  File "/home/airflow/.local/lib/python3.7/site-packages/urllib3/connectionpool.py", line 788, in urlopen
    method, url, error=e, _pool=self, _stacktrace=sys.exc_info()[2]
  File "/home/airflow/.local/lib/python3.7/site-packages/urllib3/util/retry.py", line 525, in increment
    raise six.reraise(type(error), error, _stacktrace)
  File "/home/airflow/.local/lib/python3.7/site-packages/urllib3/packages/six.py", line 770, in reraise
    raise value
  File "/home/airflow/.local/lib/python3.7/site-packages/urllib3/connectionpool.py", line 710, in urlopen
    chunked=chunked,
  File "/home/airflow/.local/lib/python3.7/site-packages/urllib3/connectionpool.py", line 398, in _make_request
    conn.request(method, url, **httplib_request_kw)
  File "/home/airflow/.local/lib/python3.7/site-packages/urllib3/connection.py", line 239, in request
    super(HTTPConnection, self).request(method, url, body=body, headers=headers)
  File "/usr/local/lib/python3.7/http/client.py", line 1281, in request
    self._send_request(method, url, body, headers, encode_chunked)
  File "/usr/local/lib/python3.7/http/client.py", line 1327, in _send_request
    self.endheaders(body, encode_chunked=encode_chunked)
  File "/usr/local/lib/python3.7/http/client.py", line 1276, in endheaders
    self._send_output(message_body, encode_chunked=encode_chunked)
  File "/usr/local/lib/python3.7/http/client.py", line 1036, in _send_output
    self.send(msg)
  File "/usr/local/lib/python3.7/http/client.py", line 976, in send
    self.connect()
  File "/home/airflow/.local/lib/python3.7/site-packages/urllib3/connection.py", line 205, in connect
    conn = self._new_conn()
  File "/home/airflow/.local/lib/python3.7/site-packages/urllib3/connection.py", line 187, in _new_conn
    self, "Failed to establish a new connection: %s" % e
urllib3.exceptions.NewConnectionError: <urllib3.connection.HTTPConnection object at 0xffff84732ad0>: Failed to establish a new connection: [Errno 111] Connection refused
[2025-02-08T14:31:26.404+0000] {base.py:299} WARNING - HEAD http://localhost:9200/ [status:N/A request:0.000s]
Traceback (most recent call last):
  File "/home/airflow/.local/lib/python3.7/site-packages/urllib3/connection.py", line 175, in _new_conn
    (self._dns_host, self.port), self.timeout, **extra_kw
  File "/home/airflow/.local/lib/python3.7/site-packages/urllib3/util/connection.py", line 95, in create_connection
    raise err
  File "/home/airflow/.local/lib/python3.7/site-packages/urllib3/util/connection.py", line 85, in create_connection
    sock.connect(sa)
ConnectionRefusedError: [Errno 111] Connection refused

During handling of the above exception, another exception occurred:

Traceback (most recent call last):
  File "/home/airflow/.local/lib/python3.7/site-packages/elasticsearch/connection/http_urllib3.py", line 252, in perform_request
    method, url, body, retries=Retry(False), headers=request_headers, **kw
  File "/home/airflow/.local/lib/python3.7/site-packages/urllib3/connectionpool.py", line 788, in urlopen
    method, url, error=e, _pool=self, _stacktrace=sys.exc_info()[2]
  File "/home/airflow/.local/lib/python3.7/site-packages/urllib3/util/retry.py", line 525, in increment
    raise six.reraise(type(error), error, _stacktrace)
  File "/home/airflow/.local/lib/python3.7/site-packages/urllib3/packages/six.py", line 770, in reraise
    raise value
  File "/home/airflow/.local/lib/python3.7/site-packages/urllib3/connectionpool.py", line 710, in urlopen
    chunked=chunked,
  File "/home/airflow/.local/lib/python3.7/site-packages/urllib3/connectionpool.py", line 398, in _make_request
    conn.request(method, url, **httplib_request_kw)
  File "/home/airflow/.local/lib/python3.7/site-packages/urllib3/connection.py", line 239, in request
    super(HTTPConnection, self).request(method, url, body=body, headers=headers)
  File "/usr/local/lib/python3.7/http/client.py", line 1281, in request
    self._send_request(method, url, body, headers, encode_chunked)
  File "/usr/local/lib/python3.7/http/client.py", line 1327, in _send_request
    self.endheaders(body, encode_chunked=encode_chunked)
  File "/usr/local/lib/python3.7/http/client.py", line 1276, in endheaders
    self._send_output(message_body, encode_chunked=encode_chunked)
  File "/usr/local/lib/python3.7/http/client.py", line 1036, in _send_output
    self.send(msg)
  File "/usr/local/lib/python3.7/http/client.py", line 976, in send
    self.connect()
  File "/home/airflow/.local/lib/python3.7/site-packages/urllib3/connection.py", line 205, in connect
    conn = self._new_conn()
  File "/home/airflow/.local/lib/python3.7/site-packages/urllib3/connection.py", line 187, in _new_conn
    self, "Failed to establish a new connection: %s" % e
urllib3.exceptions.NewConnectionError: <urllib3.connection.HTTPConnection object at 0xffff84732c90>: Failed to establish a new connection: [Errno 111] Connection refused
[2025-02-08T14:31:26.405+0000] {base.py:299} WARNING - HEAD http://localhost:9200/ [status:N/A request:0.000s]
Traceback (most recent call last):
  File "/home/airflow/.local/lib/python3.7/site-packages/urllib3/connection.py", line 175, in _new_conn
    (self._dns_host, self.port), self.timeout, **extra_kw
  File "/home/airflow/.local/lib/python3.7/site-packages/urllib3/util/connection.py", line 95, in create_connection
    raise err
  File "/home/airflow/.local/lib/python3.7/site-packages/urllib3/util/connection.py", line 85, in create_connection
    sock.connect(sa)
ConnectionRefusedError: [Errno 111] Connection refused

During handling of the above exception, another exception occurred:

Traceback (most recent call last):
  File "/home/airflow/.local/lib/python3.7/site-packages/elasticsearch/connection/http_urllib3.py", line 252, in perform_request
    method, url, body, retries=Retry(False), headers=request_headers, **kw
  File "/home/airflow/.local/lib/python3.7/site-packages/urllib3/connectionpool.py", line 788, in urlopen
    method, url, error=e, _pool=self, _stacktrace=sys.exc_info()[2]
  File "/home/airflow/.local/lib/python3.7/site-packages/urllib3/util/retry.py", line 525, in increment
    raise six.reraise(type(error), error, _stacktrace)
  File "/home/airflow/.local/lib/python3.7/site-packages/urllib3/packages/six.py", line 770, in reraise
    raise value
  File "/home/airflow/.local/lib/python3.7/site-packages/urllib3/connectionpool.py", line 710, in urlopen
    chunked=chunked,
  File "/home/airflow/.local/lib/python3.7/site-packages/urllib3/connectionpool.py", line 398, in _make_request
    conn.request(method, url, **httplib_request_kw)
  File "/home/airflow/.local/lib/python3.7/site-packages/urllib3/connection.py", line 239, in request
    super(HTTPConnection, self).request(method, url, body=body, headers=headers)
  File "/usr/local/lib/python3.7/http/client.py", line 1281, in request
    self._send_request(method, url, body, headers, encode_chunked)
  File "/usr/local/lib/python3.7/http/client.py", line 1327, in _send_request
    self.endheaders(body, encode_chunked=encode_chunked)
  File "/usr/local/lib/python3.7/http/client.py", line 1276, in endheaders
    self._send_output(message_body, encode_chunked=encode_chunked)
  File "/usr/local/lib/python3.7/http/client.py", line 1036, in _send_output
    self.send(msg)
  File "/usr/local/lib/python3.7/http/client.py", line 976, in send
    self.connect()
  File "/home/airflow/.local/lib/python3.7/site-packages/urllib3/connection.py", line 205, in connect
    conn = self._new_conn()
  File "/home/airflow/.local/lib/python3.7/site-packages/urllib3/connection.py", line 187, in _new_conn
    self, "Failed to establish a new connection: %s" % e
urllib3.exceptions.NewConnectionError: <urllib3.connection.HTTPConnection object at 0xffff847227d0>: Failed to establish a new connection: [Errno 111] Connection refused
[2025-02-08T14:31:26.405+0000] {base.py:299} WARNING - HEAD http://localhost:9200/ [status:N/A request:0.000s]
Traceback (most recent call last):
  File "/home/airflow/.local/lib/python3.7/site-packages/urllib3/connection.py", line 175, in _new_conn
    (self._dns_host, self.port), self.timeout, **extra_kw
  File "/home/airflow/.local/lib/python3.7/site-packages/urllib3/util/connection.py", line 95, in create_connection
    raise err
  File "/home/airflow/.local/lib/python3.7/site-packages/urllib3/util/connection.py", line 85, in create_connection
    sock.connect(sa)
ConnectionRefusedError: [Errno 111] Connection refused

During handling of the above exception, another exception occurred:

Traceback (most recent call last):
  File "/home/airflow/.local/lib/python3.7/site-packages/elasticsearch/connection/http_urllib3.py", line 252, in perform_request
    method, url, body, retries=Retry(False), headers=request_headers, **kw
  File "/home/airflow/.local/lib/python3.7/site-packages/urllib3/connectionpool.py", line 788, in urlopen
    method, url, error=e, _pool=self, _stacktrace=sys.exc_info()[2]
  File "/home/airflow/.local/lib/python3.7/site-packages/urllib3/util/retry.py", line 525, in increment
    raise six.reraise(type(error), error, _stacktrace)
  File "/home/airflow/.local/lib/python3.7/site-packages/urllib3/packages/six.py", line 770, in reraise
    raise value
  File "/home/airflow/.local/lib/python3.7/site-packages/urllib3/connectionpool.py", line 710, in urlopen
    chunked=chunked,
  File "/home/airflow/.local/lib/python3.7/site-packages/urllib3/connectionpool.py", line 398, in _make_request
    conn.request(method, url, **httplib_request_kw)
  File "/home/airflow/.local/lib/python3.7/site-packages/urllib3/connection.py", line 239, in request
    super(HTTPConnection, self).request(method, url, body=body, headers=headers)
  File "/usr/local/lib/python3.7/http/client.py", line 1281, in request
    self._send_request(method, url, body, headers, encode_chunked)
  File "/usr/local/lib/python3.7/http/client.py", line 1327, in _send_request
    self.endheaders(body, encode_chunked=encode_chunked)
  File "/usr/local/lib/python3.7/http/client.py", line 1276, in endheaders
    self._send_output(message_body, encode_chunked=encode_chunked)
  File "/usr/local/lib/python3.7/http/client.py", line 1036, in _send_output
    self.send(msg)
  File "/usr/local/lib/python3.7/http/client.py", line 976, in send
    self.connect()
  File "/home/airflow/.local/lib/python3.7/site-packages/urllib3/connection.py", line 205, in connect
    conn = self._new_conn()
  File "/home/airflow/.local/lib/python3.7/site-packages/urllib3/connection.py", line 187, in _new_conn
    self, "Failed to establish a new connection: %s" % e
urllib3.exceptions.NewConnectionError: <urllib3.connection.HTTPConnection object at 0xffff84732bd0>: Failed to establish a new connection: [Errno 111] Connection refused
[2025-02-08T14:31:26.406+0000] {logging_mixin.py:115} INFO -  Connection to Elasticsearch failed
[2025-02-08T14:31:26.406+0000] {python.py:173} INFO - Done. Returned value was: None
[2025-02-08T14:31:26.416+0000] {taskinstance.py:1412} INFO - Marking task as SUCCESS. dag_id=pipeline_milestone_3, task_id=upload_to_elasticsearch, execution_date=20250208T143123, start_date=20250208T143126, end_date=20250208T143126
[2025-02-08T14:31:26.441+0000] {local_task_job.py:156} INFO - Task exited with return code 0
[2025-02-08T14:31:26.507+0000] {local_task_job.py:279} INFO - 0 downstream tasks scheduled from follow-on schedule check
