[2025-02-10T07:56:04.119+0000] {taskinstance.py:1171} INFO - Dependencies all met for <TaskInstance: pipeline_milestone_3.extract_data scheduled__2025-02-09T00:00:00+00:00 [queued]>
[2025-02-10T07:56:04.123+0000] {taskinstance.py:1171} INFO - Dependencies all met for <TaskInstance: pipeline_milestone_3.extract_data scheduled__2025-02-09T00:00:00+00:00 [queued]>
[2025-02-10T07:56:04.123+0000] {taskinstance.py:1368} INFO - 
--------------------------------------------------------------------------------
[2025-02-10T07:56:04.123+0000] {taskinstance.py:1369} INFO - Starting attempt 1 of 1
[2025-02-10T07:56:04.123+0000] {taskinstance.py:1370} INFO - 
--------------------------------------------------------------------------------
[2025-02-10T07:56:04.130+0000] {taskinstance.py:1389} INFO - Executing <Task(PythonOperator): extract_data> on 2025-02-09 00:00:00+00:00
[2025-02-10T07:56:04.134+0000] {standard_task_runner.py:52} INFO - Started process 278 to run task
[2025-02-10T07:56:04.137+0000] {standard_task_runner.py:79} INFO - Running: ['***', 'tasks', 'run', 'pipeline_milestone_3', 'extract_data', 'scheduled__2025-02-09T00:00:00+00:00', '--job-id', '5', '--raw', '--subdir', 'DAGS_FOLDER/P2M3_azka_irsyad_DAG.py', '--cfg-path', '/tmp/tmpvb3y5uen', '--error-file', '/tmp/tmpmv4vc9l5']
[2025-02-10T07:56:04.138+0000] {standard_task_runner.py:80} INFO - Job 5: Subtask extract_data
[2025-02-10T07:56:04.192+0000] {task_command.py:371} INFO - Running <TaskInstance: pipeline_milestone_3.extract_data scheduled__2025-02-09T00:00:00+00:00 [running]> on host c7bd35cc3dd3
[2025-02-10T07:56:04.256+0000] {taskinstance.py:1583} INFO - Exporting the following env vars:
AIRFLOW_CTX_DAG_OWNER=Azka
AIRFLOW_CTX_DAG_ID=pipeline_milestone_3
AIRFLOW_CTX_TASK_ID=extract_data
AIRFLOW_CTX_EXECUTION_DATE=2025-02-09T00:00:00+00:00
AIRFLOW_CTX_TRY_NUMBER=1
AIRFLOW_CTX_DAG_RUN_ID=scheduled__2025-02-09T00:00:00+00:00
[2025-02-10T07:56:04.269+0000] {taskinstance.py:1902} ERROR - Task failed with exception
Traceback (most recent call last):
  File "/home/airflow/.local/lib/python3.7/site-packages/airflow/operators/python.py", line 171, in execute
    return_value = self.execute_callable()
  File "/home/airflow/.local/lib/python3.7/site-packages/airflow/operators/python.py", line 189, in execute_callable
    return self.python_callable(*self.op_args, **self.op_kwargs)
  File "/opt/airflow/dags/P2M3_azka_irsyad_DAG.py", line 18, in extract
    source_conn = source_hook.get_conn()
  File "/home/airflow/.local/lib/python3.7/site-packages/airflow/providers/postgres/hooks/postgres.py", line 86, in get_conn
    conn = deepcopy(self.connection or self.get_connection(conn_id))
  File "/home/airflow/.local/lib/python3.7/site-packages/airflow/hooks/base.py", line 67, in get_connection
    conn = Connection.get_connection_from_secrets(conn_id)
  File "/home/airflow/.local/lib/python3.7/site-packages/airflow/models/connection.py", line 430, in get_connection_from_secrets
    raise AirflowNotFoundException(f"The conn_id `{conn_id}` isn't defined")
airflow.exceptions.AirflowNotFoundException: The conn_id `172.18.0.2` isn't defined
[2025-02-10T07:56:04.275+0000] {taskinstance.py:1412} INFO - Marking task as FAILED. dag_id=pipeline_milestone_3, task_id=extract_data, execution_date=20250209T000000, start_date=20250210T075604, end_date=20250210T075604
[2025-02-10T07:56:04.289+0000] {standard_task_runner.py:97} ERROR - Failed to execute job 5 for task extract_data (The conn_id `172.18.0.2` isn't defined; 278)
[2025-02-10T07:56:04.317+0000] {local_task_job.py:156} INFO - Task exited with return code 1
[2025-02-10T07:56:04.338+0000] {local_task_job.py:279} INFO - 0 downstream tasks scheduled from follow-on schedule check
