[2025-02-09T16:09:00.425+0000] {taskinstance.py:1171} INFO - Dependencies all met for <TaskInstance: pipeline_milestone_3.extract_data manual__2025-02-09T16:08:58.570392+00:00 [queued]>
[2025-02-09T16:09:00.434+0000] {taskinstance.py:1171} INFO - Dependencies all met for <TaskInstance: pipeline_milestone_3.extract_data manual__2025-02-09T16:08:58.570392+00:00 [queued]>
[2025-02-09T16:09:00.434+0000] {taskinstance.py:1368} INFO - 
--------------------------------------------------------------------------------
[2025-02-09T16:09:00.434+0000] {taskinstance.py:1369} INFO - Starting attempt 1 of 1
[2025-02-09T16:09:00.435+0000] {taskinstance.py:1370} INFO - 
--------------------------------------------------------------------------------
[2025-02-09T16:09:00.442+0000] {taskinstance.py:1389} INFO - Executing <Task(PythonOperator): extract_data> on 2025-02-09 16:08:58.570392+00:00
[2025-02-09T16:09:00.453+0000] {standard_task_runner.py:52} INFO - Started process 707 to run task
[2025-02-09T16:09:00.456+0000] {standard_task_runner.py:79} INFO - Running: ['***', 'tasks', 'run', 'pipeline_milestone_3', 'extract_data', 'manual__2025-02-09T16:08:58.570392+00:00', '--job-id', '90', '--raw', '--subdir', 'DAGS_FOLDER/P2M3_azka_irsyad_DAG.py', '--cfg-path', '/tmp/tmpuk_1_hwg', '--error-file', '/tmp/tmp6omwc8hc']
[2025-02-09T16:09:00.458+0000] {standard_task_runner.py:80} INFO - Job 90: Subtask extract_data
[2025-02-09T16:09:00.519+0000] {task_command.py:371} INFO - Running <TaskInstance: pipeline_milestone_3.extract_data manual__2025-02-09T16:08:58.570392+00:00 [running]> on host fac8a5123a60
[2025-02-09T16:09:00.573+0000] {taskinstance.py:1583} INFO - Exporting the following env vars:
AIRFLOW_CTX_DAG_OWNER=Azka
AIRFLOW_CTX_DAG_ID=pipeline_milestone_3
AIRFLOW_CTX_TASK_ID=extract_data
AIRFLOW_CTX_EXECUTION_DATE=2025-02-09T16:08:58.570392+00:00
AIRFLOW_CTX_TRY_NUMBER=1
AIRFLOW_CTX_DAG_RUN_ID=manual__2025-02-09T16:08:58.570392+00:00
[2025-02-09T16:09:00.584+0000] {taskinstance.py:1902} ERROR - Task failed with exception
Traceback (most recent call last):
  File "/home/airflow/.local/lib/python3.7/site-packages/airflow/operators/python.py", line 171, in execute
    return_value = self.execute_callable()
  File "/home/airflow/.local/lib/python3.7/site-packages/airflow/operators/python.py", line 189, in execute_callable
    return self.python_callable(*self.op_args, **self.op_kwargs)
  File "/opt/airflow/dags/P2M3_azka_irsyad_DAG.py", line 18, in extract
    source_conn = source_hook.get_conn()
  File "/home/airflow/.local/lib/python3.7/site-packages/airflow/providers/postgres/hooks/postgres.py", line 86, in get_conn
    conn = deepcopy(self.connection or self.get_connection(conn_id))
  File "/home/airflow/.local/lib/python3.7/site-packages/airflow/hooks/base.py", line 67, in get_connection
    conn = Connection.get_connection_from_secrets(conn_id)
  File "/home/airflow/.local/lib/python3.7/site-packages/airflow/models/connection.py", line 430, in get_connection_from_secrets
    raise AirflowNotFoundException(f"The conn_id `{conn_id}` isn't defined")
airflow.exceptions.AirflowNotFoundException: The conn_id `***_postgres` isn't defined
[2025-02-09T16:09:00.590+0000] {taskinstance.py:1412} INFO - Marking task as FAILED. dag_id=pipeline_milestone_3, task_id=extract_data, execution_date=20250209T160858, start_date=20250209T160900, end_date=20250209T160900
[2025-02-09T16:09:00.597+0000] {standard_task_runner.py:97} ERROR - Failed to execute job 90 for task extract_data (The conn_id `***_postgres` isn't defined; 707)
[2025-02-09T16:09:00.635+0000] {local_task_job.py:156} INFO - Task exited with return code 1
[2025-02-09T16:09:00.658+0000] {local_task_job.py:279} INFO - 0 downstream tasks scheduled from follow-on schedule check
